Traceback (most recent call last):
  File "/usr/lib/python3/dist-packages/pkg_resources/__init__.py", line 2859, in get_entry_map
    ep_map = self._ep_map
  File "/usr/lib/python3/dist-packages/pkg_resources/__init__.py", line 2817, in __getattr__
    raise AttributeError(attr)
AttributeError: _ep_map

During handling of the above exception, another exception occurred:

Traceback (most recent call last):
  File "setup.py", line 5, in <module>
    setup(
  File "/usr/lib/python3/dist-packages/setuptools/__init__.py", line 143, in setup
    _install_setup_requires(attrs)
  File "/usr/lib/python3/dist-packages/setuptools/__init__.py", line 131, in _install_setup_requires
    dist = distutils.core.Distribution(dict(
  File "/usr/lib/python3/dist-packages/setuptools/dist.py", line 445, in __init__
    for ep in pkg_resources.iter_entry_points('distutils.setup_keywords'):
  File "/usr/lib/python3/dist-packages/pkg_resources/__init__.py", line 657, in <genexpr>
    for entry in dist.get_entry_map(group).values()
  File "/usr/lib/python3/dist-packages/pkg_resources/__init__.py", line 2861, in get_entry_map
    ep_map = self._ep_map = EntryPoint.parse_map(
  File "/usr/lib/python3/dist-packages/pkg_resources/__init__.py", line 2529, in parse_map
    for group, lines in data:
  File "/usr/lib/python3/dist-packages/pkg_resources/__init__.py", line 3201, in split_sections
    for line in yield_lines(s):
  File "/usr/lib/python3/dist-packages/pkg_resources/__init__.py", line 2389, in yield_lines
    for ss in strs:
  File "/usr/lib/python3/dist-packages/pkg_resources/__init__.py", line 2768, in _get_metadata
    if self.has_metadata(name):
  File "/usr/lib/python3/dist-packages/pkg_resources/__init__.py", line 1415, in has_metadata
    return self._has(path)
  File "/usr/lib/python3/dist-packages/pkg_resources/__init__.py", line 1605, in _has
    return os.path.exists(path)
  File "/usr/lib/python3.8/genericpath.py", line 19, in exists
    os.stat(path)
KeyboardInterrupt
